Workbook

Sheet Payroll
A1: ลำดับ | B1: รหัสพนักงาน | C1: ชื่อ - นามสกุล | D1: ตำแหน่ง | E1: แผนก | F1: อัตราเงินเดือน | G1: เงินได้ | N1: เงินหัก | T1: รวมเงินได้สุทธิ
G2: ค่าแรง | H2: ค่าตำแหน่ง | I2: OT | J2: พิเศษ | K2: โบนัส | L2: เงินได้อื่นๆ | M2: รวมเงินได้ | N2: ประกันสังคม | O2: ภาษีเงินได้ | P2: สำรองเลี้ยงชีพ | Q2: เงินเบิก | R2: หักอื่นๆ | S2: รวมเงินหัก
A3: 1 | B3: 1001 | C3: สัมพันธ์ นาทะคำ | D3: - | E3: - | G3: 5133.1467 | I3: 2566.56 | J3: 600 | K3: 0 | L3: 0 | M3: =SUM(G3:K3) -> 8299.7067 | N3: 256.65733 | O3: 0 | Q3: 0 | R3: 0 | S3: =SUM(N3:R3) -> 256.65733 | T3: =+M3-S3 -> 8043.0493
A4: 2 | B4: 1002 | C4: สมพงษ์ แก้วบุดดา | D4: - | E4: - | G4: 6533.338 | I4: 3266.62 | J4: 7800 | M4: =SUM(G4:K4) -> 17599.958 | N4: 326.6669 | Q4: 0 | S4: =SUM(N4:R4) -> 326.6669 | T4: =+M4-S4 -> 17273.291
A5: 3 | B5: 1003 | C5: อนัน เนื่องแอม | D5: - | E5: - | G5: 6066.6707 | I5: 3033.29 | J5: 7800 | M5: =SUM(G5:K5) -> 16899.961 | N5: 303.33353 | Q5: 0 | S5: =SUM(N5:R5) -> 303.33353 | T5: =+M5-S5 -> 16596.627
A6: 4 | B6: 1004 | C6: ศักดิ์ดา | D6: - | E6: - | G6: 5600 | I6: 2799.96 | J6: 0 | M6: =SUM(G6:K6) -> 8399.96 | N6: 280 | Q6: 0 | S6: =SUM(N6:R6) -> 280 | T6: =+M6-S6 -> 8119.96
A7: 5 | B7: 1005 | C7: นพรุธ คำน้อย | D7: - | E7: - | G7: 4666 | I7: 2333 | J7: 0 | M7: =SUM(G7:K7) -> 6999 | N7: 233.3 | Q7: 3000 | S7: =SUM(N7:R7) -> 3233.3 | T7: =+M7-S7 -> 3765.7
A8: 6 | B8: 1006 | C8: ณัฐวุฒิ อู่เงิน | D8: - | E8: - | G8: 6099.9567 | I8: 3046.53 | J8: 900 | M8: =SUM(G8:K8) -> 10046.487 | N8: 304.99783 | Q8: 3000 | S8: =SUM(N8:R8) -> 3304.9978 | T8: =+M8-S8 -> 6741.4888
A9: 7 | B9: 1007 | C9: นัฐพล ประดับราช | D9: - | E9: - | G9: 3349.96 | I9: 1565.58 | J9: 0 | M9: =SUM(G9:K9) -> 4915.54 | N9: 167.498 | Q9: 0 | S9: =SUM(N9:R9) -> 167.498 | T9: =+M9-S9 -> 4748.042
A10: 8 | B10: 1008 | C10: ธนากร อิทธิกุล | D10: - | E10: - | G10: 3033.31 | I10: 1514.8 | J10: 0 | M10: =SUM(G10:K10) -> 4548.11 | N10: 151.6655 | Q10: 0 | S10: =SUM(N10:R10) -> 151.6655 | T10: =+M10-S10 -> 4396.4445
A11: 9 | B11: 1009 | C11: มานนท์ | D11: - | E11: - | G11: 4549.9667 | I11: 2164 | J11: 0 | M11: =SUM(G11:K11) -> 6713.9667 | Q11: 3000 | S11: =SUM(N11:R11) -> 3000 | T11: =+M11-S11 -> 3713.9667
A12: 10 | B12: 1010 | C12: อาโบ (กระเหรี่ยง) | D12: - | E12: - | G12: 4799.9667 | I12: 2397.33 | J12: 0 | M12: =SUM(G12:K12) -> 7197.2967 | Q12: 0 | S12: =SUM(N12:R12) -> 0 | T12: =+M12-S12 -> 7197.2967
A13: 11 | B13: 1011 | C13: ประหยัด เล็กกลาง | D13: - | E13: - | G13: 1733.32 | I13: 865.6 | J13: 0 | M13: =SUM(G13:K13) -> 2598.92 | N13: 86.666 | Q13: 0 | S13: =SUM(N13:R13) -> 86.666 | T13: =+M13-S13 -> 2512.254
A14: 12 | B14: 1012 | C14: วรพรรณ อุ่นจิตร | D14: - | E14: - | G14: 5199.96 | I14: 2380.4 | J14: 0 | M14: =SUM(G14:K14) -> 7580.36 | N14: 259.998 | Q14: 0 | S14: =SUM(N14:R14) -> 259.998 | T14: =+M14-S14 -> 7320.362
A15: 13 | B15: 1013 | C15: จิรภัทร คันทา | D15: - | E15: - | G15: 5199.96 | I15: 2380.4 | J15: 0 | M15: =SUM(G15:K15) -> 7580.36 | Q15: 2000 | S15: =SUM(N15:R15) -> 2000 | T15: =+M15-S15 -> 5580.36
A16: 14 | B16: 1014 | C16: เอกชัย นามเสนา | D16: - | E16: - | G16: 6066.62 | I16: 3029.6 | J16: 3600 | M16: =SUM(G16:K16) -> 12696.22 | N16: 303.331 | Q16: 3000 | S16: =SUM(N16:R16) -> 3303.331 | T16: =+M16-S16 -> 9392.889
A17: 15 | B17: 1015 | C17: สวรรค์ สายทอง | D17: - | E17: - | G17: 4284 | I17: 2160 | J17: 0 | M17: =SUM(G17:K17) -> 6444 | N17: 214.2 | Q17: 0 | S17: =SUM(N17:R17) -> 214.2 | T17: =+M17-S17 -> 6229.8
A18: 16 | B18: 1016 | C18: วัชรชัย ชิณวงศ์พรหม | D18: - | E18: - | G18: 4641 | I18: 2340 | J18: 0 | M18: =SUM(G18:K18) -> 6981 | N18: 232.05 | Q18: 3000 | S18: =SUM(N18:R18) -> 3232.05 | T18: =+M18-S18 -> 3748.95
A19: 17 | B19: 1017 | C19: น้ำฝน ชูนาค | D19: - | E19: - | G19: 4998 | I19: 2520 | J19: 0 | M19: =SUM(G19:K19) -> 7518 | N19: 249.9 | Q19: 3000 | S19: =SUM(N19:R19) -> 3249.9 | T19: =+M19-S19 -> 4268.1
A20: 18 | B20: 1018 | C20: กมลวรรณ อ่อนนุ่ม | D20: - | E20: - | G20: 4284 | I20: 2160 | J20: 0 | M20: =SUM(G20:K20) -> 6444 | Q20: 2000 | S20: =SUM(N20:R20) -> 2000 | T20: =+M20-S20 -> 4444
A21: 19 | B21: 1019 | C21: ใบเตี้ย สายพรม | D21: - | E21: - | G21: 3570 | I21: 1800 | J21: 185 | M21: =SUM(G21:K21) -> 5555 | N21: 178.5 | Q21: 3000 | S21: =SUM(N21:R21) -> 3178.5 | T21: =+M21-S21 -> 2376.5
A22: 20 | B22: 1020 | C22: ณัฐริกา มนตรี | D22: - | E22: - | G22: 3927 | I22: 1980 | J22: 185 | M22: =SUM(G22:K22) -> 6092 | N22: 196.35 | Q22: 3000 | S22: =SUM(N22:R22) -> 3196.35 | T22: =+M22-S22 -> 2895.65
A23: 21 | B23: 1021 | C23: มาริษา หอมหวน | D23: - | E23: - | G23: 4642 | I23: 2340 | J23: 537 | M23: =SUM(G23:K23) -> 7519 | Q23: 3000 | S23: =SUM(N23:R23) -> 3000 | T23: =+M23-S23 -> 4519
A24: 22 | B24: 1022 | C24: นางอุไรรัตน์ ดามัง | D24: - | E24: - | G24: 4641 | I24: 2340 | J24: 537 | M24: =SUM(G24:K24) -> 7518 | N24: 232.05 | Q24: 3000 | S24: =SUM(N24:R24) -> 3232.05 | T24: =+M24-S24 -> 4285.95
A25: 23 | B25: 1023 | C25: สุมิตรา เลิศฤทธิ์ | D25: - | E25: - | G25: 2499 | I25: 1260 | J25: 150 | M25: =SUM(G25:K25) -> 3909 | N25: 124.95 | Q25: 0 | S25: =SUM(N25:R25) -> 124.95 | T25: =+M25-S25 -> 3784.05
A26: 24 | B26: 1024 | C26: ยุทธนา เตยสันเที๊ยะ | D26: - | E26: - | G26: 4641 | I26: 2340 | J26: 0 | M26: =SUM(G26:K26) -> 6981 | N26: 232.05 | Q26: 3000 | S26: =SUM(N26:R26) -> 3232.05 | T26: =+M26-S26 -> 3748.95
A27: 25 | B27: 1025 | C27: อรอนงค์ จันทร์เทียน | D27: - | E27: - | G27: 4641 | I27: 2340 | J27: 0 | M27: =SUM(G27:K27) -> 6981 | N27: 232.05 | Q27: 3000 | S27: =SUM(N27:R27) -> 3232.05 | T27: =+M27-S27 -> 3748.95
A28: 26 | B28: 1026 | C28: นภัทร (กระเหรี่ยง) | D28: - | E28: - | G28: 1071 | I28: 540 | J28: 0 | M28: =SUM(G28:K28) -> 1611 | Q28: 0 | S28: =SUM(N28:R28) -> 0 | T28: =+M28-S28 -> 1611
A29: 27 | B29: 1027 | C29: ตาโบ้ (กระเหรี่ยง) | D29: - | E29: - | G29: 0 | I29: 0 | J29: 0 | M29: =SUM(G29:K29) -> 0 | Q29: 0 | S29: =SUM(N29:R29) -> 0 | T29: =+M29-S29 -> 0
A30: 28 | B30: 1028 | C30: มนต่มบี้ (กระเหรี่ยง) | D30: - | E30: - | G30: 0 | I30: 0 | J30: 0 | M30: =SUM(G30:K30) -> 0 | Q30: 0 | S30: =SUM(N30:R30) -> 0 | T30: =+M30-S30 -> 0
A31: 29 | B31: 1029 | C31: ขจรชัย (กระเหรี่ยง) | D31: - | E31: - | G31: 3570 | I31: 1800 | J31: 0 | M31: =SUM(G31:K31) -> 5370 | Q31: 0 | S31: =SUM(N31:R31) -> 0 | T31: =+M31-S31 -> 5370
A32: 30 | B32: 1030 | C32: โป้โบ (กระเหรี่ยง) | D32: - | E32: - | G32: 4998 | I32: 2520 | J32: 13 | M32: =SUM(G32:K32) -> 7531 | Q32: 0 | S32: =SUM(N32:R32) -> 0 | T32: =+M32-S32 -> 7531
A33: 31 | B33: 1031 | C33: อานนท์ นาบุญ | D33: - | E33: - | G33: 3570 | I33: 1800 | J33: 0 | M33: =SUM(G33:K33) -> 5370 | Q33: 2500 | S33: =SUM(N33:R33) -> 2500 | T33: =+M33-S33 -> 2870
A34: 32 | B34: 1032 | C34: วรรณ อู่เงิน | D34: - | E34: - | G34: 4998 | I34: 2520 | J34: 0 | M34: =SUM(G34:K34) -> 7518 | N34: 249.9 | Q34: 3000 | S34: =SUM(N34:R34) -> 3249.9 | T34: =+M34-S34 -> 4268.1
A35: 33 | B35: 1033 | C35: ปรางค์ทอง แก้วฤาชา | D35: - | E35: - | G35: 4284 | I35: 2160 | J35: 537 | M35: =SUM(G35:K35) -> 6981 | N35: 214.2 | Q35: 3000 | S35: =SUM(N35:R35) -> 3214.2 | T35: =+M35-S35 -> 3766.8
A36: 34 | B36: 1034 | C36: นางดวงใจ ชื่นชม | D36: - | E36: - | G36: 0 | I36: 0 | J36: 0 | M36: =SUM(G36:K36) -> 0 | N36: 0 | Q36: 0 | S36: =SUM(N36:R36) -> 0 | T36: =+M36-S36 -> 0
A37: 35 | B37: 1035 | C37: ดวงแข หารศึก | D37: - | E37: - | G37: 0 | I37: 0 | J37: 0 | M37: =SUM(G37:K37) -> 0 | N37: 0 | Q37: 0 | S37: =SUM(N37:R37) -> 0 | T37: =+M37-S37 -> 0
A38: 36 | B38: 1036 | C38: น้ำอ้อย โพธิ์ทอง | D38: - | E38: - | G38: 3945 | I38: 1980 | J38: 0 | M38: =SUM(G38:K38) -> 5925 | N38: 197.25 | Q38: 3000 | S38: =SUM(N38:R38) -> 3197.25 | T38: =+M38-S38 -> 2727.75
A39: 37 | B39: 1037 | C39: มณีรัตน์ เดนดง | D39: - | E39: - | G39: 3927 | I39: 1980 | J39: 0 | M39: =SUM(G39:K39) -> 5907 | Q39: 3000 | S39: =SUM(N39:R39) -> 3000 | T39: =+M39-S39 -> 2907
A40: 38 | B40: 1038 | C40: อรสา แสงจันทร์ | D40: - | E40: - | G40: 4998 | I40: 2520 | J40: 240 | M40: =SUM(G40:K40) -> 7758 | N40: 249.9 | Q40: 0 | S40: =SUM(N40:R40) -> 249.9 | T40: =+M40-S40 -> 7508.1
...

Sheet Slip
B1: หจก.วิราญกร | V1: *** ลิ้งค์ ข้อมูล ด้วย รหัสพนักงาน
B2: ใบจ่ายเงินเดือน (Pay Slip) | V2: เปลี่ยน รหัสพนักงาน ข้อมูลเปลี่ยนตาม
B4: รหัสพนักงาน : | E4: 1002 | K4: ตำแหน่ง : | N4: {=INDEX(Payroll!D:D,MATCH(E4,Payroll!B:B))} -> -
B5: ชื่อ - นามสกุล : | E5: {=INDEX(Payroll!C:C,MATCH(E4,Payroll!B:B))} -> สมพงษ์ แก้วบุดดา | K5: แผนก : | N5: {=INDEX(Payroll!E:E,MATCH(E4,Payroll!B:B))} -> -
B6: วันที่จ่าย : | E6: 46152 | K6: ค่าจ้างเดือน : | N6: 16-30/04/2026
B8: เงินได้ | K8: เงินหัก
B9: เงินเดือน | E9: {=INDEX(Payroll!G:G,MATCH(E4,Payroll!B:B))} -> 6533.338 | I9: บาท | K9: ประกันสังคม | N9: {=INDEX(Payroll!N:N,MATCH(E4,Payroll!B:B))} -> 326.6669 | R9: บาท
B10: ค่าตำแหน่ง | E10: {=INDEX(Payroll!H:H,MATCH(E4,Payroll!B:B))} -> 0 | I10: บาท | K10: เงินเบิก | N10: =INDEX(Payroll!Q:Q,MATCH(E4,Payroll!B:B)) -> 0 | R10: บาท
B11: OT | E11: {=INDEX(Payroll!I:I,MATCH(E4,Payroll!B:B))} -> 3266.62 | I11: บาท | K11: หักอื่นๆ | N11: =INDEX(Payroll!R:R,MATCH(E4,Payroll!B:B)) -> 0 | R11: บาท
B12: พิเศษ | E12: {=INDEX(Payroll!J:J,MATCH(E4,Payroll!B:B))} -> 7800 | I12: บาท
B15: รวมเงินได้ | E15: =SUM(E9:H14) -> 17599.958 | I15: บาท | K15: รวมเงินหัก | N15: =SUM(N9:Q14) -> 326.6669 | R15: บาท
K17: รวมเงินได้สุทธิ | N17: =E15-N15 -> 17273.291 | R17: บาท
B19: ลงชื่อผู้จ่ายเงิน | K19: ลงชื่อผู้รับเงิน
